Exception during reset or similar
Traceback (most recent call last):
  File "C:\Python35\lib\site-packages\sqlalchemy\pool.py", line 636, in _finalize_fairy
    fairy._reset(pool)
  File "C:\Python35\lib\site-packages\sqlalchemy\pool.py", line 776, in _reset
    pool._dialect.do_rollback(self)
  File "C:\Python35\lib\site-packages\sqlalchemy\engine\default.py", line 420, in do_rollback
    dbapi_connection.rollback()
sqlite3.ProgrammingError: SQLite objects created in a thread can only be used in that same thread.The object was created in thread id 12800 and this is thread id 3272
Exception closing connection <sqlite3.Connection object at 0x037BA020>
Traceback (most recent call last):
  File "C:\Python35\lib\site-packages\sqlalchemy\pool.py", line 636, in _finalize_fairy
    fairy._reset(pool)
  File "C:\Python35\lib\site-packages\sqlalchemy\pool.py", line 776, in _reset
    pool._dialect.do_rollback(self)
  File "C:\Python35\lib\site-packages\sqlalchemy\engine\default.py", line 420, in do_rollback
    dbapi_connection.rollback()
sqlite3.ProgrammingError: SQLite objects created in a thread can only be used in that same thread.The object was created in thread id 12800 and this is thread id 3272

During handling of the above exception, another exception occurred:

Traceback (most recent call last):
  File "C:\Python35\lib\site-packages\sqlalchemy\pool.py", line 290, in _close_connection
    self._dialect.do_close(connection)
  File "C:\Python35\lib\site-packages\sqlalchemy\engine\default.py", line 426, in do_close
    dbapi_connection.close()
sqlite3.ProgrammingError: SQLite objects created in a thread can only be used in that same thread.The object was created in thread id 12800 and this is thread id 3272
Exception during reset or similar
Traceback (most recent call last):
  File "C:\Python35\lib\site-packages\sqlalchemy\pool.py", line 636, in _finalize_fairy
    fairy._reset(pool)
  File "C:\Python35\lib\site-packages\sqlalchemy\pool.py", line 776, in _reset
    pool._dialect.do_rollback(self)
  File "C:\Python35\lib\site-packages\sqlalchemy\engine\default.py", line 420, in do_rollback
    dbapi_connection.rollback()
sqlite3.ProgrammingError: SQLite objects created in a thread can only be used in that same thread.The object was created in thread id 13064 and this is thread id 3272
Exception closing connection <sqlite3.Connection object at 0x03279DF0>
Traceback (most recent call last):
  File "C:\Python35\lib\site-packages\sqlalchemy\pool.py", line 636, in _finalize_fairy
    fairy._reset(pool)
  File "C:\Python35\lib\site-packages\sqlalchemy\pool.py", line 776, in _reset
    pool._dialect.do_rollback(self)
  File "C:\Python35\lib\site-packages\sqlalchemy\engine\default.py", line 420, in do_rollback
    dbapi_connection.rollback()
sqlite3.ProgrammingError: SQLite objects created in a thread can only be used in that same thread.The object was created in thread id 13064 and this is thread id 3272

During handling of the above exception, another exception occurred:

Traceback (most recent call last):
  File "C:\Python35\lib\site-packages\sqlalchemy\pool.py", line 290, in _close_connection
    self._dialect.do_close(connection)
  File "C:\Python35\lib\site-packages\sqlalchemy\engine\default.py", line 426, in do_close
    dbapi_connection.close()
sqlite3.ProgrammingError: SQLite objects created in a thread can only be used in that same thread.The object was created in thread id 13064 and this is thread id 3272
Exception during reset or similar
Traceback (most recent call last):
  File "C:\Python35\lib\site-packages\sqlalchemy\pool.py", line 636, in _finalize_fairy
    fairy._reset(pool)
  File "C:\Python35\lib\site-packages\sqlalchemy\pool.py", line 776, in _reset
    pool._dialect.do_rollback(self)
  File "C:\Python35\lib\site-packages\sqlalchemy\engine\default.py", line 420, in do_rollback
    dbapi_connection.rollback()
sqlite3.ProgrammingError: SQLite objects created in a thread can only be used in that same thread.The object was created in thread id 776 and this is thread id 3272
Exception closing connection <sqlite3.Connection object at 0x037BA2C8>
Traceback (most recent call last):
  File "C:\Python35\lib\site-packages\sqlalchemy\pool.py", line 636, in _finalize_fairy
    fairy._reset(pool)
  File "C:\Python35\lib\site-packages\sqlalchemy\pool.py", line 776, in _reset
    pool._dialect.do_rollback(self)
  File "C:\Python35\lib\site-packages\sqlalchemy\engine\default.py", line 420, in do_rollback
    dbapi_connection.rollback()
sqlite3.ProgrammingError: SQLite objects created in a thread can only be used in that same thread.The object was created in thread id 776 and this is thread id 3272

During handling of the above exception, another exception occurred:

Traceback (most recent call last):
  File "C:\Python35\lib\site-packages\sqlalchemy\pool.py", line 290, in _close_connection
    self._dialect.do_close(connection)
  File "C:\Python35\lib\site-packages\sqlalchemy\engine\default.py", line 426, in do_close
    dbapi_connection.close()
sqlite3.ProgrammingError: SQLite objects created in a thread can only be used in that same thread.The object was created in thread id 776 and this is thread id 3272
Exception during reset or similar
Traceback (most recent call last):
  File "C:\Python35\lib\site-packages\sqlalchemy\pool.py", line 636, in _finalize_fairy
    fairy._reset(pool)
  File "C:\Python35\lib\site-packages\sqlalchemy\pool.py", line 776, in _reset
    pool._dialect.do_rollback(self)
  File "C:\Python35\lib\site-packages\sqlalchemy\engine\default.py", line 420, in do_rollback
    dbapi_connection.rollback()
sqlite3.ProgrammingError: SQLite objects created in a thread can only be used in that same thread.The object was created in thread id 5112 and this is thread id 3272
Exception closing connection <sqlite3.Connection object at 0x037BA130>
Traceback (most recent call last):
  File "C:\Python35\lib\site-packages\sqlalchemy\pool.py", line 636, in _finalize_fairy
    fairy._reset(pool)
  File "C:\Python35\lib\site-packages\sqlalchemy\pool.py", line 776, in _reset
    pool._dialect.do_rollback(self)
  File "C:\Python35\lib\site-packages\sqlalchemy\engine\default.py", line 420, in do_rollback
    dbapi_connection.rollback()
sqlite3.ProgrammingError: SQLite objects created in a thread can only be used in that same thread.The object was created in thread id 5112 and this is thread id 3272

During handling of the above exception, another exception occurred:

Traceback (most recent call last):
  File "C:\Python35\lib\site-packages\sqlalchemy\pool.py", line 290, in _close_connection
    self._dialect.do_close(connection)
  File "C:\Python35\lib\site-packages\sqlalchemy\engine\default.py", line 426, in do_close
    dbapi_connection.close()
sqlite3.ProgrammingError: SQLite objects created in a thread can only be used in that same thread.The object was created in thread id 5112 and this is thread id 3272
